<?xml version="1.0"?>
<robot xmlns:xacro="http://www.ros.org/wiki/xacro">

    <xacro:include filename="inertial_macros.xacro" />

    <material name="white">
        <color rgba="1 1 1 1" />
    </material>

    <material name="orange">
        <color rgba="1 0.3 0.1 1" />
    </material>

    <material name="blue">
        <color rgba="0.2 0.2 1 1" />
    </material>

    <material name="black">
        <color rgba="0 0 0 1" />
    </material>
    
    <material name="red">
        <color rgba="1 0 0 1" />
    </material>

    <!-- BASE LINK -->
    <link name="base_link">
    </link>

    <!-- BASE_FOOTPRINT LINK -->

    <joint name="base_footprint_joint" type="fixed">
        <parent link="base_link"/>
        <child link="base_footprint"/>
        <origin xyz="0 0 0" rpy="0 0 0"/>
    </joint>

    <link name="base_footprint">
    </link>

    <!-- CHASSIS LINK -->
    <joint name="chassis_joint" type="fixed">
        <parent link="base_link"/>
        <child link="chassis"/>
        <origin xyz="0 0 0"/>
    </joint>

    <link name="chassis">
        <visual>
            <origin xyz="0 0 0.1125"/>
            <geometry>
                <box size="0.7 1 0.225"/>
            </geometry>
            <material name="white"/>
        </visual>
        <collision>
            <origin xyz="0 0 0.1125"/>
            <geometry>
                <box size="0.7 1.0 0.225"/>
            </geometry>
        </collision>
        <xacro:inertial_box mass="0.5" x="0.7" y="1.0" z="0.225">
            <origin xyz="0 0 0.1125" rpy="0 0 0" />
        </xacro:inertial_box>
    </link>

    <gazebo reference="chassis">
        <material>Gazebo/White</material>
    </gazebo>

    <!-- LEFT WHEEL LINK -->
    <joint name="back_left_wheel_joint" type="continuous">
        <parent link="base_link"/>
        <child link="left_wheel"/>
        <origin xyz="0.25 0.525 0" rpy="-${pi/2} 0 0" />
        <axis xyz="0 0 1"/>
    </joint>

    <link name="left_wheel">
        <visual>
            <geometry>
                <cylinder radius="0.076" length="0.04"/>
            </geometry>
            <material name="blue"/>
        </visual>
        <collision>
            <geometry>
                <cylinder radius="0.076" length="0.04"/>
            </geometry>
        </collision>
        <xacro:inertial_cylinder mass="0.5" length="0.04" radius="0.076">
            <origin xyz="0 0 0" rpy="0 0 0" />
        </xacro:inertial_cylinder>
    </link>

    <gazebo reference="left_wheel">
        <material>Gazebo/Blue</material>
        <mu1 value="5.0"/>
        <mu2 value="5.0"/>
    </gazebo>

    <!-- RIGHT WHEEL LINK -->
    <joint name="back_right_wheel_joint" type="continuous">
        <parent link="base_link"/>
        <child link="right_wheel"/>
        <origin xyz="0.25 -0.525 0" rpy="${pi/2} 0 0" />
        <axis xyz="0 0 -1"/>
    </joint>

    <link name="right_wheel">
        <visual>
            <geometry>
                <cylinder radius="0.076" length="0.04"/>
            </geometry>
            <material name="blue"/>
        </visual>
        <collision>
            <geometry>
                <cylinder radius="0.076" length="0.04"/>
            </geometry>
        </collision>
        <xacro:inertial_cylinder mass="0.5" length="0.04" radius="0.076">
            <origin xyz="0 0 0" rpy="0 0 0" />
        </xacro:inertial_cylinder>
    </link>

    <gazebo reference="right_wheel">
        <material>Gazebo/Blue</material>
        <mu1 value="5.0"/>
        <mu2 value="5.0"/>
    </gazebo>

    <!-- RIGHT FRONT WHEEL LINK -->
    <joint name="front_right_wheel_joint" type="continuous">
        <parent link="base_link" />
        <child link="right_front_wheel" />
        <origin xyz="-0.25 -0.525 0" rpy="${pi/2} 0 0" />
        <axis xyz="0 0 -1" />
    </joint>

    <link name="right_front_wheel">
        <visual>
            <geometry>
                <cylinder radius="0.076" length="0.04" />
            </geometry>
            <material name="blue" />
        </visual>
        <collision>
            <geometry>
                <cylinder radius="0.076" length="0.04" />
            </geometry>
        </collision>
        <xacro:inertial_cylinder mass="0.5" length="0.04" radius="0.076">
            <origin xyz="0 0 0" rpy="0 0 0" />
        </xacro:inertial_cylinder>
    </link>

    <gazebo reference="right_front_wheel">
        <material>Gazebo/Blue</material>
        <mu1 value="5.0"/>
        <mu2 value="5.0"/>
    </gazebo>

    <!-- LEFT FRONT WHEEL LINK -->
    <joint name="front_left_wheel_joint" type="continuous">
        <parent link="base_link" />
        <child link="left_front_wheel" />
        <origin xyz="-0.25 0.525 0" rpy="-${pi/2} 0 0" />
        <axis xyz="0 0 1" />
    </joint>

    <link name="left_front_wheel">
        <visual>
            <geometry>
                <cylinder radius="0.076" length="0.04" />
            </geometry>
            <material name="blue" />
        </visual>
        <collision>
            <geometry>
                <cylinder radius="0.076" length="0.04" />
            </geometry>
        </collision>
        <xacro:inertial_cylinder mass="0.5" length="0.04" radius="0.076">
            <origin xyz="0 0 0" rpy="0 0 0" />
        </xacro:inertial_cylinder>
    </link>

    <gazebo reference="left_front_wheel">
        <material>Gazebo/Blue</material>
       <mu1 value="5.0"/>
        <mu2 value="5.0"/>
    </gazebo>

    <!-- IMU LINK -->
    <joint name="imu_joint" type="fixed">
        <parent link="base_link" />
        <child link="imu_link" />
        <origin xyz="0 0 0" rpy="0 0 0" />
    </joint>

    <link name="imu_link">
        <visual>
            <geometry>
                <box size="0.01 0.01 0.01" />
            </geometry>
            <material name="white" />
        </visual>
        <collision>
            <geometry>
                <box size="0.01 0.01 0.01" />
            </geometry>
        </collision>
        <xacro:inertial_box mass="0.1" x="0.01" y="0.01" z="0.01">
            <origin xyz="0 0 0" rpy="0 0 0" />
        </xacro:inertial_box>
    </link>

    <gazebo reference="imu_link">
        <material>Gazebo/White</material>
    </gazebo>

</robot>